from passlib.context import CryptContext
from datetime import datetime, timedelta
from jose import jwt, JWTError
from fastapi import Depends, HTTPException
from fastapi.security import OAuth2PasswordBearer
from sqlalchemy.orm import Session
from . import models, database
import os

SECRET_KEY = os.getenv("SECRET_KEY", "supersecret")
ALGORITHM = "HS256"
ACCESS_TOKEN_EXPIRE_MINUTES = 60

pwd_context = CryptContext(schemes=["bcrypt"], deprecated="auto")
oauth2_scheme = OAuth2PasswordBearer(tokenUrl="login")


def get_password_hash(password: str):
    return pwd_context.hash(password)


def verify_password(plain, hashed):
    return pwd_context.verify(plain, hashed)


def create_access_token(data: dict, expires_delta: timedelta = None):
    to_encode = data.copy()
    expire = datetime.utcnow() + (
        expires_delta
        if expires_delta
        else timedelta(minutes=ACCESS_TOKEN_EXPIRE_MINUTES)
    )
    to_encode.update({"exp": expire})
    return jwt.encode(to_encode, SECRET_KEY, algorithm=ALGORITHM)


def get_current_user(
    token: str = Depends(oauth2_scheme), db: Session = Depends(database.get_db)
):
    credentials_exception = HTTPException(
        status_code=401, detail="Could not validate credentials"
    )
    try:
        payload = jwt.decode(token, SECRET_KEY, algorithms=[ALGORITHM])
        user_id = int(payload.get("sub"))
        user = db.query(models.User).filter(models.User.id == user_id).first()
        if not user:
            raise credentials_exception
        return user
    except JWTError:
        raise credentials_exception
